Workbook
Name A: [1]ANÁLISE!$BI$17:$BI$2000
Name AAA: #REF!
Name ANA: #REF!
Name Análise: #REF!
Name COMPOSIÇÕES: #REF!
Name CR: #REF!
Name DADOS: #REF!
Name DESC: [2]DADOS_READ!$C$19:$G$1500
Name IC: [3]ANÁLISE!#REF!
Name IC: '[4]ANÁLISE PREÇO'!#REF!
Name IC: #REF!
Name II: #REF!
Name IL: [2]LOCAIS!$C$6:$C$46
Name IM: #REF!
Name IS: [3]ANÁLISE!#REF!
Name IS: '[4]ANÁLISE PREÇO'!#REF!
Name IS: #REF!
Name IT: #REF!
Name MTX_READ: [2]DADOS_READ!$C$19:$M$1501
Name ORÇAMENTO: [5]Orçamento!$1:$1048576
Name orçasin: '[6]ORÇA. ANÁLISE'!$A$9:$G$266
Name PAD: [2]DADOS_BASICOS!$D$25
Name S: #REF!
Name S_1: #REF!
Name S_10: #REF!
Name S_11: #REF!
Name S_12: #REF!
Name S_2: #REF!
Name S_3: #REF!
Name S_4: #REF!
Name S_5: #REF!
Name S_6: #REF!
Name S_7: #REF!
Name S_8: #REF!
Name S_9: #REF!
Name SD: [2]READ!$H$1513
Name T_1: #REF!
Name T_10: #REF!
Name T_11: #REF!
Name T_12: #REF!
Name T_2: #REF!
Name T_3: #REF!
Name T_4: #REF!
Name T_5: #REF!
Name T_6: #REF!
Name T_7: #REF!
Name T_8: #REF!
Name T_9: #REF!
Name TG: #REF!
Name TVA: [2]MEDIÇÃO!$S$1502
Name TVM: [2]MEDIÇÃO!$T$1502
Name TVP: [2]MEDIÇÃO!$O$1502
Name TVR: [2]MEDIÇÃO!$P$1502
Name TVS: [2]MEDIÇÃO!$V$1502
Name VL_LICITADO: [2]READ!$H$1508
Name VPL: [2]READ!$H$1508
Name VPR: [2]READ!$H$1512

Sheet DADOS
C4: DADOS DA OBRA
C7: OBJETO DO CONTRATO | D7: CONSTITUI O PRESENTE OBJETO A CONTRATAÇÃO DE EMPRESA ESPECIALIZADA PARA EXECUÇÃO DE OBRA DA COBERTURA DA QUADRA POLIESPORTIVA DO 8º BATALHÃO DE POLICIA MILITAR, LOCALIZADO NA RUA PROF. MARIO PINOTI, 218, NOVA CRUZ/RN.
C9: EMPRESA | D9: CONARTE PROJETOS CONSTRUÇÕES E SERVIÇOS LTDA
C11: Nº CONTRATO | D11: 057/2025 | F11: Nº MEDIÇÃO | H11: 108/2026 | J11: MEDIÇÃO Nº | L11: 2
C13: DATA ORDEM SERVIÇO | D13: 46008 | F13: DATA MEDIÇÃO | H13: 01/06/2026 a 21/06/2026
C16: DATA BASE (Io) | D16: 10/09/2025 | H16: Cliente:
C18: PRAZO OBRA | D18: 120 | E18: Dias | H18: GOVERNO DO ESTADO DO RIO GRANDE DO NORTE
C20: PRAZO ADITIVADO | D20: 0 | E20: Dias
C22: TEMPO DE PARALIZAÇÃO | D22: 0 | E22: Dias | H22: SUB-COORDENADORIA DE FISCALIZAÇÃO E CONTROLE
C24: PRAZO TOTAL | D24: =D18+D20+D22 -> 120 | E24: Dias | H24: OBRA FISCALIZADA PELA:
C26: BDI (%) | D26: 0.2663 | H26: SECRETARIA DE ESTADO DA INFRAESTUTURA DO RN
C28: MAXIMO A ADITIVAR (%) | D28: 0.5
D30: DADOS DO FISCAL
C32: NOME | D32: VICTOR HUGO GOMES
C34: FUNÇÃO | D34: ENGENHEIRO CIVIL | H34: MATRICULA FUNCIONAL
C36: ENTIDADE DE CLASSE | D36: CREA | H36: REGISTRO PROFISSIONAL
M38: V4.1.02.15

Sheet PLANILHA
A1: PLANILHA DE MEDIÇÕES PADRÃO - SIN
A3: GOVERNO DO ESTADO DO RIO GRANDE DO NORTE
A4: SECRETARIA DE INFRA-ESTRUTURA - SIN
A5: COORDENADORIA DE OBRAS E SERVIÇOS DE ENGENHARIA
A6: SUB-COORDENADORIA DE FISCALIZAÇÃO E CONTROLE
A8: OBRA: | B8: =DADOS!D7 -> CONSTITUI O PRESENTE OBJETO A CONTRATAÇÃO DE EMPRESA ESPECIALIZADA PARA EXECUÇÃO DE OBRA DA COBERTURA DA QUADRA POLIESPORTIVA DO 8º BATALHÃO DE POLICIA MILITAR, LOCALIZADO NA RUA PROF. MARIO PINOTI, 218, NOVA CRUZ/RN. | C8: CONTRATO.: | E8: MEDIÇÃO: CONTROLE Nº | F8: DATA ORDEM DE SERVIÇO: | G8: MEDIÇÃO DA OBRA | H8: PRAZO DE EXECUÇÃO DA OBRA: | I8: DATA DA MEDIÇÃO: | J8: DATA BASE DA PLANILHA BASE: | K8: EMPRESA EXECUTORA: | L8: =DADOS!D9 -> CONARTE PROJETOS CONSTRUÇÕES E SERVIÇOS LTDA
C9: =DADOS!D11 -> 057/2025 | E9: =DADOS!H11 -> 108/2026 | F9: =DADOS!D13 -> 46008 | G9: =DADOS!L11 -> 2 | H9: =DADOS!D24 -> 120 | I9: =DADOS!H13 -> 01/06/2026 a 21/06/2026 | J9: =DADOS!D16 -> 10/09/2025
A10: BOLETIM DE MEDIÇÃO Nº 02 | T10: AVISO | U10: AVISO | V10: AVISO | W10: AVISO | X10: AVISO
A11: ITEM | B11: DESCRIÇÃO | C11: QUANTIDADE | H11: PERCENTUAL | J11: VALORES
C12: UNID | D12: PREVISTO | E12: NO PERÍODO | F12: ACUMULADO | G12: SALDO | H12: NO PERÍODO | I12: ACUMULADO | J12: PREÇO UNIT. | K12: PREVISTO | L12: NO PERÍODO | M12: ACUMULADO | N12: SALDO | Q12: TOTAL | R12: SALDO | S12: ACUMULADO | T12: 1ª Medição | U12: 2ª Medição | V12: 3ª Medição | W12: 4ª Medição | X12: 5ª Medição
A13: 1. | B13: SERVIÇOS PRELIMINARES | K13: =SUM(K14:K20) -> 23460.26 | L13: =SUM(L14:L20) -> 6195.01 | M13: =SUM(M14:M20) -> 16027.88 | N13: =SUM(N14:N20) -> 7432.38
A14: 1.1 | B14: ADMINISTRAÇÃO LOCAL DA OBRA | C14: UN | D14: 1 | E14: ='M. DE CÁLCULO'!K20 -> 0.35 | F14: =S14+E14 -> 0.58 | G14: =D14-F14 -> 0.42 | H14: =E14/D14 -> 0.35 | I14: =F14/D14 -> 0.58 | J14: 17695.49 | K14: =(D14*$J14) -> 17695.49 | L14: 6195.01 | M14: =TRUNC(F14*$J14,2) -> 10263.38 | N14: =K14-M14 -> 7432.11 | Q14: =L14 -> 6195.01 | R14: =D14-S14-E14 -> 0.42 | S14: =SUM(T14:X14) -> 0.23 | T14: 0.23
A15: 1.2 | B15: REGULARIZAÇÃO DE OBRA - ART - 2025 | C15: UN | D15: 1 | E15: =VLOOKUP(A15,'M. DE CÁLCULO'!$A$17:$N$843,12,0) -> 0 | F15: =S15+E15 -> 1 | G15: =D15-F15 -> 0 | H15: =E15/D15 -> 0 | I15: =F15/D15 -> 1 | J15: 332.45 | K15: =TRUNC(D15*$J15,2) -> 332.45 | L15: =TRUNC(E15*$J15,2) -> 0 | M15: =TRUNC(F15*$J15,2) -> 332.45 | N15: =K15-M15 -> 0 | Q15: =L15 -> 0 | R15: =D15-S15-E15 -> 0 | S15: =SUM(T15:X15) -> 1 | T15: 1
A16: 1.3 | B16: FORNECIMENTO E INSTALAÇÃO DE PLACA DE OBRA COM CHAPA GALVANIZADA E ESTRUTURA DE MADEIRA. AF_03/2022_PS | C16: m² | D16: 6 | E16: =VLOOKUP(A16,'M. DE CÁLCULO'!$A$17:$N$843,12,0) -> 0 | F16: =S16+E16 -> 6 | G16: =D16-F16 -> 0 | H16: =E16/D16 -> 0 | I16: =F16/D16 -> 1 | J16: 527.68 | K16: =TRUNC(D16*$J16,2) -> 3166.08 | L16: =TRUNC(E16*$J16,2) -> 0 | M16: =TRUNC(F16*$J16,2) -> 3166.08 | N16: =K16-M16 -> 0 | Q16: =L16 -> 0 | R16: =D16-S16-E16 -> 0 | S16: =SUM(T16:X16) -> 6 | T16: 6
A17: 1.4 | B17: MOBILIZAÇÃO DE EQUIPAMENTOS EM CAMINHÃO EQUIPADO COM GUINDASTE | C17: KM | D17: 50 | E17: =VLOOKUP(A17,'M. DE CÁLCULO'!$A$17:$N$843,12,0) -> 0 | F17: =S17+E17 -> 50 | G17: =D17-F17 -> 0 | H17: =E17/D17 -> 0 | I17: =F17/D17 -> 1 | J17: 5 | K17: =TRUNC(D17*$J17,2) -> 250 | L17: =TRUNC(E17*$J17,2) -> 0 | M17: =TRUNC(F17*$J17,2) -> 250 | N17: =K17-M17 -> 0 | Q17: =L17 -> 0 | R17: =D17-S17-E17 -> 0 | S17: =SUM(T17:X17) -> 50 | T17: 50
A18: 1.5 | B18: DEMOLIÇÃO DE PISO DE CIMENTADO SOBRE LASTRO DE CONCRETO SIMPLES/CALCETAMENTO. R_11/2020 | C18: m² | D18: 23.66 | E18: =VLOOKUP(A18,'M. DE CÁLCULO'!$A$17:$N$843,12,0) -> 0 | F18: =S18+E18 -> 23.65 | G18: =D18-F18 -> 0.01 | H18: =E18/D18 -> 0 | I18: =F18/D18 -> 0.9996 | J18: 27 | K18: =TRUNC(D18*$J18,2) -> 638.82 | L18: =TRUNC(E18*$J18,2) -> 0 | M18: =TRUNC(F18*$J18,2) -> 638.55 | N18: =K18-M18 -> 0.27 | Q18: =L18 -> 0 | R18: =D18-S18-E18 -> 0.01 | S18: =SUM(T18:X18) -> 23.65 | T18: 23.65
A19: 1.6 | B19: DEMOLIÇÃO DE ALVENARIA DE BLOCO FURADO, DE FORMA MANUAL, SEM REAPROVEITAMENTO. AF_09/2023 | C19: m³ | D19: 3.46 | E19: =VLOOKUP(A19,'M. DE CÁLCULO'!$A$17:$N$843,12,0) -> 0 | F19: =S19+E19 -> 3.46 | G19: =D19-F19 -> 0 | H19: =E19/D19 -> 0 | I19: =F19/D19 -> 1 | J19: 70.11 | K19: =TRUNC(D19*$J19,2) -> 242.58 | L19: =TRUNC(E19*$J19,2) -> 0 | M19: =TRUNC(F19*$J19,2) -> 242.58 | N19: =K19-M19 -> 0 | Q19: =L19 -> 0 | R19: =D19-S19-E19 -> 0 | S19: =SUM(T19:X19) -> 3.46 | T19: 3.46
A20: 1.7 | B20: REMOÇÃO DE POSTE DE CONCRETO ARMADO SEÇÃO CIRCULAR OU DUPLO T. INC_05/2021 | C20: un | D20: 3 | E20: =VLOOKUP(A20,'M. DE CÁLCULO'!$A$17:$N$843,12,0) -> 0 | F20: =S20+E20 -> 3 | G20: =D20-F20 -> 0 | H20: =E20/D20 -> 0 | I20: =F20/D20 -> 1 | J20: 378.28 | K20: =TRUNC(D20*$J20,2) -> 1134.84 | L20: =TRUNC(E20*$J20,2) -> 0 | M20: =TRUNC(F20*$J20,2) -> 1134.84 | N20: =K20-M20 -> 0 | S20: =SUM(T20:X20) -> 3 | T20: 3
A21: 2 | B21: MOVIMENTO DE TERRA | K21: =SUM(K22:K24) -> 3292.14 | L21: =SUM(L22:L24) -> 26.88 | M21: =SUM(M22:M24) -> 3118.72 | N21: =SUM(N22:N24) -> 173.42
A22: 2.1 | B22: ESCAVAÇÃO MANUAL PARA BLOCO DE COROAMENTO OU SAPATA (INCLUINDO ESCAVAÇÃO PARA COLOCAÇÃO DE FÔRMAS). AF_01/2024 | C22: m³ | D22: 23.96 | E22: =VLOOKUP(A22,'M. DE CÁLCULO'!$A$17:$N$843,12,0) -> 0 | F22: =S22+E22 -> 23.76 | G22: =D22-F22 -> 0.2 | H22: =E22/D22 -> 0 | I22: =F22/D22 -> 0.9917 | J22: 114.43 | K22: =D22*J22 -> 2741.74 | L22: =TRUNC(E22*$J22,2) -> 0 | M22: =TRUNC(F22*$J22,2) -> 2718.85 | N22: =K22-M22 -> 22.89 | Q22: =L22 -> 0 | R22: =D22-S22-E22 -> 0.2 | S22: =SUM(T22:X22) -> 23.76 | T22: 23.76
A23: 2.2 | B23: ATERRO MANUAL COM AREIA PARA ATERRO E APILOADO COM SOQUETE EM CAMADAS DE 20 CM. R_11/2019 | C23: m³ | D23: 0.9 | E23: =VLOOKUP(A23,'M. DE CÁLCULO'!$A$17:$N$843,12,0) -> 0.2 | F23: =S23+E23 -> 0.9 | G23: =D23-F23 -> 0 | H23: =E23/D23 -> 0.2222 | I23: =F23/D23 -> 1 | J23: 134.41 | K23: =TRUNC(D23*J23,2) -> 120.96 | L23: =TRUNC(E23*$J23,2) -> 26.88 | M23: =TRUNC(F23*$J23,2) -> 120.96 | N23: =K23-M23 -> 0 | Q23: =L23 -> 26.88 | R23: =D23-S23-E23 -> 0 | S23: =SUM(T23:X23) -> 0.7 | T23: 0.7
A24: 2.3 | B24: REATERRO MANUAL DE VALAS, COM PLACA VIBRATÓRIA. AF_08/2023 | C24: m³ | D24: 16.09 | E24: =VLOOKUP(A24,'M. DE CÁLCULO'!$A$17:$N$843,12,0) -> 0 | F24: =S24+E24 -> 10.45 | G24: =D24-F24 -> 5.64 | H24: =E24/D24 -> 0 | I24: =F24/D24 -> 0.6495 | J24: 26.69 | K24: =D24*J24 -> 429.44 | L24: =TRUNC(E24*$J24,2) -> 0 | M24: =TRUNC(F24*$J24,2) -> 278.91 | N24: =K24-M24 -> 150.53 | Q24: =L24 -> 0 | R24: =D24-S24-E24 -> 5.64 | S24: =SUM(T24:X24) -> 10.45 | T24: 10.45
A25: 3 | B25: FUNDAÇÃO | K25: =SUM(K26:K28) -> 11915.13 | L25: =SUM(L26:L28) -> 342.38 | M25: =SUM(M26:M28) -> 11497.88 | N25: =SUM(N26:N28) -> 417.25
A26: 3.1 | B26: LASTRO DE CONCRETO MAGRO, APLICADO EM BLOCOS DE COROAMENTO OU SAPATAS, ESPESSURA DE 5 CM. AF_01/2024 | C26: m² | D26: 14 | E26: =VLOOKUP(A26,'M. DE CÁLCULO'!$A$17:$N$843,12,0) -> 0 | F26: =S26+E26 -> 14 | G26: =D26-F26 -> 0 | H26: =E26/D26 -> 0 | I26: =F26/D26 -> 1 | J26: 45.46 | K26: =D26*J26 -> 636.44 | L26: =TRUNC(E26*$J26,2) -> 0 | M26: =TRUNC(F26*$J26,2) -> 636.44 | N26: =K26-M26 -> 0 | Q26: =L26 -> 0 | R26: =D26-S26-E26 -> 0 | S26: =SUM(T26:X26) -> 14 | T26: 14
A27: 3.2 | B27: FABRICAÇÃO, MONTAGEM E DESMONTAGEM DE FÔRMA PARA BLOCO DE COROAMENTO, EM CHAPA DE MADEIRA COMPENSADA RESINADA, E=17 MM, 4 UTILIZAÇÕES. AF_01/2024 | C27: m² | D27: 35.84 | E27: =VLOOKUP(A27,'M. DE CÁLCULO'!$A$17:$N$843,12,0) -> 2.08 | F27: =S27+E27 -> 34.08 | G27: =D27-F27 -> 1.76 | H27: =E27/D27 -> 0.058 | I27: =F27/D27 -> 0.9509 | J27: 164.61 | K27: =D27*J27 -> 5899.62 | L27: =TRUNC(E27*$J27,2) -> 342.38 | M27: =TRUNC(F27*$J27,2) -> 5609.9 | N27: =K27-M27 -> 289.72 | Q27: =L27 -> 342.38 | R27: =D27-S27-E27 -> 1.76 | S27: =SUM(T27:X27) -> 32 | T27: 32
A28: 3.3 | B28: CONCRETO CICLÓPICO FCK = 25MPA, 30% PEDRA DE MÃO EM VOLUME REAL, INCLUSIVE LANÇAMENTO. R_11/2021 | C28: m³ | D28: 7.17 | E28: =VLOOKUP(A28,'M. DE CÁLCULO'!$A$17:$N$843,12,0) -> 0 | F28: =S28+E28 -> 7 | G28: =D28-F28 -> 0.17 | H28: =E28/D28 -> 0 | I28: =F28/D28 -> 0.9763 | J28: 750.22 | K28: =TRUNC(D28*J28,2) -> 5379.07 | L28: =TRUNC(E28*$J28,2) -> 0 | M28: =TRUNC(F28*$J28,2) -> 5251.54 | N28: =K28-M28 -> 127.53 | Q28: =L28 -> 0 | R28: =D28-S28-E28 -> 0.17 | S28: =SUM(T28:X28) -> 7 | T28: 7
A29: 4 | B29: ESTRUTURA | K29: =SUM(K30:K31) -> 194187.12 | L29: =SUM(L30:L31) -> 115035.58 | M29: =SUM(M30:M31) -> 160136.02 | N29: =SUM(N30:N31) -> 34051.1
A30: 4.1 | B30: ESTRUTURA METÁLICA P/ COBERTURA C/VIGAS-TRELIÇA PRATT E TERÇAS EM UDC 127, 2 ÁGUAS, SEM LANTERNIN, VÃOS 10,01 A 20,0M, PINTADA 1 D OXIDO FERRO + 2 D ESMALTE EPÓXI BRANCO, EXCETO FORN. TELHAS - EXECUTADA | C30: m² | D30: 657 | E30: =VLOOKUP(A30,'M. DE CÁLCULO'!$A$17:$N$843,12,0) -> 504.14 | F30: =S30+E30 -> 504.14 | G30: =D30-F30 -> 152.86 | H30: =E30/D30 -> 0.7673 | I30: =F30/D30 -> 0.7673 | J30: 222.76 | K30: =TRUNC(D30*J30,2) -> 146353.32 | L30: =TRUNC(E30*$J30,2) -> 112302.22 | M30: =TRUNC(F30*$J30,2) -> 112302.22 | N30: =K30-M30 -> 34051.1 | Q30: =L30 -> 112302.22 | R30: =D30-S30-E30 -> 152.86 | S30: =SUM(T30:X30) -> 0 | T30: 0
A31: 4.2 | B31: COLUNA METÁLICA, EM PERFIS UDC127X50X5,13, DIAGONAIS DUPLAS, DIVERSOS USOS OU COMPOSIÇÃO DE PÓRTICOS VÃOS 10,01M A 20,0M,, LARGURA 0,60M, PDMAX. 7,00 , PINTURA 01 DEMÃO EPOXI FUNDO ÓXIDO FERRO + 02 DEMÃOS ESMALTE EPOXI BRANCO | C31: M | D31: 70 | E31: =VLOOKUP(A31,'M. DE CÁLCULO'!$A$17:$N$843,12,0) -> 4 | F31: =S31+E31 -> 70 | G31: =D31-F31 -> 0 | H31: =E31/D31 -> 0.0571 | I31: =F31/D31 -> 1 | J31: 683.34 | K31: =TRUNC(D31*J31,2) -> 47833.8 | L31: =TRUNC(E31*$J31,2) -> 2733.36 | M31: =TRUNC(F31*$J31,2) -> 47833.8 | N31: =K31-M31 -> 0 | Q31: =L31 -> 2733.36 | R31: =D31-S31-E31 -> 0 | S31: =SUM(T31:X31) -> 66 | T31: 66
A32: 5 | B32: PAREDES E PAINÉIS | K32: =SUM(K33:K33) -> 4140.29 | L32: =SUM(L33:L33) -> 303.82 | M32: =SUM(M33:M33) -> 4129.08 | N32: =SUM(N33:N33) -> 11.21
A33: 5.1 | B33: ALVENARIA EM TIJOLO CERÂMICO FURADO 9X19X19CM, 1 VEZ (ESPESSURA 19 CM), ASSENTADO EM ARGAMASSA TRAÇO 1:4 (CIMENTO E AREIA MÉDIA), PREPARO MANUAL, JUNTA 1 CM. INC_11/2016 | C33: m² | D33: 33.25 | E33: =VLOOKUP(A33,'M. DE CÁLCULO'!$A$17:$N$843,12,0) -> 2.44 | F33: =S33+E33 -> 33.16 | G33: =D33-F33 -> 0.09 | H33: =E33/D33 -> 0.0734 | I33: =F33/D33 -> 0.9973 | J33: 124.52 | K33: =TRUNC(D33*J33,2) -> 4140.29 | L33: =TRUNC(E33*$J33,2) -> 303.82 | M33: =TRUNC(F33*$J33,2) -> 4129.08 | N33: =K33-M33 -> 11.21 | Q33: =L33 -> 303.82 | R33: =D33-S33-E33 -> 0.09 | S33: =SUM(T33:X33) -> 30.72 | T33: 30.72
A34: 6 | B34: COBERTURA | K34: =SUM(K35:K35) -> 53217 | L34: =SUM(L35:L35) -> 0 | M34: =SUM(M35:M35) -> 0 | N34: =SUM(N35:N35) -> 53217
A35: 6.1 | B35: TELHAMENTO COM TELHA DE AÇO/ALUMÍNIO E = 0,5 MM, COM ATÉ 2 ÁGUAS, INCLUSO IÇAMENTO. AF_07/2019 | C35: m² | D35: 657 | E35: =VLOOKUP(A35,'M. DE CÁLCULO'!$A$17:$N$843,12,0) -> 0 | F35: =S35+E35 -> 0 | G35: =D35-F35 -> 657 | H35: =E35/D35 -> 0 | I35: =F35/D35 -> 0 | J35: 81 | K35: =TRUNC(D35*J35,2) -> 53217 | L35: =TRUNC(E35*$J35,2) -> 0 | M35: =TRUNC(F35*$J35,2) -> 0 | N35: =K35-M35 -> 53217 | Q35: =L35 -> 0 | R35: =D35-S35-E35 -> 657 | S35: =SUM(T35:X35) -> 0 | T35: 0
A36: 7 | B36: INSTALAÇÕES ELÉTRICAS | K36: =SUM(K37:K50) -> 18336.48 | L36: =SUM(L37:L50) -> 0 | M36: =SUM(M37:M50) -> 0 | N36: =SUM(N37:N50) -> 18336.48
A37: 7.1 | B37: REFLETOR SLIM LED 100W DE POTÊNCIA, BRANCO FRIO, 6500K, AUTOVOLT, MARCA G-LIGHT OU SIMILAR | C37: UN | D37: 30 | E37: =VLOOKUP(A37,'M. DE CÁLCULO'!$A$17:$N$843,12,0) -> 0 | F37: =S37+E37 -> 0 | G37: =D37-F37 -> 30 | H37: =E37/D37 -> 0 | I37: =F37/D37 -> 0 | J37: 93.45 | K37: =D37*J37 -> 2803.5 | L37: =TRUNC(E37*$J37,2) -> 0 | M37: =TRUNC(F37*$J37,2) -> 0 | N37: =K37-M37 -> 2803.5 | Q37: =L37 -> 0 | R37: =D37-S37-E37 -> 30 | S37: =SUM(T37:X37) -> 0 | T37: 0
A38: 7.2 | B38: ELETRODUTO RÍGIDO SOLDÁVEL, PVC, DN 32 MM (1"), APARENTE - FORNECIMENTO E INSTALAÇÃO. AF_10/2022 | C38: M | D38: 200 | E38: =VLOOKUP(A38,'M. DE CÁLCULO'!$A$17:$N$843,12,0) -> 0 | F38: =S38+E38 -> 0 | G38: =D38-F38 -> 200 | H38: =E38/D38 -> 0 | I38: =F38/D38 -> 0 | J38: 29.89 | K38: =D38*J38 -> 5978 | L38: =TRUNC(E38*$J38,2) -> 0 | M38: =TRUNC(F38*$J38,2) -> 0 | N38: =K38-M38 -> 5978 | Q38: =L38 -> 0 | R38: =D38-S38-E38 -> 200 | S38: =SUM(T38:X38) -> 0 | T38: 0
A39: 7.3 | B39: CURVA 90° PVC RIGIDO SOLDAVEL MARROM, D= 32MM (1''), APARENTE - FORNECIMENTO E INSTALAÇÃO. | C39: UN | D39: 10 | E39: =VLOOKUP(A39,'M. DE CÁLCULO'!$A$17:$N$843,12,0) -> 0 | F39: =S39+E39 -> 0 | G39: =D39-F39 -> 10 | H39: =E39/D39 -> 0 | I39: =F39/D39 -> 0 | J39: 23.71 | K39: =D39*J39 -> 237.1 | L39: =TRUNC(E39*$J39,2) -> 0 | M39: =TRUNC(F39*$J39,2) -> 0 | N39: =K39-M39 -> 237.1 | Q39: =L39 -> 0 | R39: =D39-S39-E39 -> 10 | S39: =SUM(T39:X39) -> 0 | T39: 0
A40: 7.4 | B40: CONDULETE DE PVC, TIPO C, PARA ELETRODUTO DE PVC SOLDÁVEL DN 32 MM (1''), APARENTE - FORNECIMENTO E INSTALAÇÃO. AF_10/2022 | C40: UN | D40: 21 | E40: =VLOOKUP(A40,'M. DE CÁLCULO'!$A$17:$N$843,12,0) -> 0 | F40: =S40+E40 -> 0 | G40: =D40-F40 -> 21 | H40: =E40/D40 -> 0 | I40: =F40/D40 -> 0 | J40: 37.26 | K40: =D40*J40 -> 782.46 | L40: =TRUNC(E40*$J40,2) -> 0 | M40: =TRUNC(F40*$J40,2) -> 0 | N40: =K40-M40 -> 782.46 | Q40: =L40 -> 0 | R40: =D40-S40-E40 -> 21 | S40: =SUM(T40:X40) -> 0 | T40: 0
A41: 7.5 | B41: CONDULETE DE PVC, TIPO E, PARA ELETRODUTO DE PVC SOLDÁVEL DN 32 MM (1''), APARENTE - FORNECIMENTO E INSTALAÇÃO. AF_10/2022 | C41: UN | D41: 3 | E41: =VLOOKUP(A41,'M. DE CÁLCULO'!$A$17:$N$843,12,0) -> 0 | F41: =S41+E41 -> 0 | G41: =D41-F41 -> 3 | H41: =E41/D41 -> 0 | I41: =F41/D41 -> 0 | J41: 30.4 | K41: =D41*J41 -> 91.2 | L41: =TRUNC(E41*$J41,2) -> 0 | M41: =TRUNC(F41*$J41,2) -> 0 | N41: =K41-M41 -> 91.2 | T41: 0
A42: 7.6 | B42: CONDULETE DE PVC, TIPO T, PARA ELETRODUTO DE PVC SOLDÁVEL DN 32 MM (1''), APARENTE - FORNECIMENTO E INSTALAÇÃO. AF_10/2022 | C42: UN | D42: 3 | E42: =VLOOKUP(A42,'M. DE CÁLCULO'!$A$17:$N$843,12,0) -> 0 | F42: =S42+E42 -> 0 | G42: =D42-F42 -> 3 | H42: =E42/D42 -> 0 | I42: =F42/D42 -> 0 | J42: 52.31 | K42: =D42*J42 -> 156.93 | L42: =TRUNC(E42*$J42,2) -> 0 | M42: =TRUNC(F42*$J42,2) -> 0 | N42: =K42-M42 -> 156.93 | T42: 0
...

Sheet M. DE CÁLCULO
O2: OBRA S/ ADM REFORMA: | P2: =PLANILHA!K69-PLANILHA!K14 -> 317304.51 | S2: OBRA S/ ADM REFORMA: | T2: =SUM(PLANILHA!K13:K68)/2 -> 335000
A3: GOVERNO DO ESTADO DO RIO GRANDE DO NORTE | O3: MEDIÇÃO ACUMULADA: | P3: =PLANILHA!L69 -> 124193.35 | Q3: 246352.6 | S3: OBRA S/ ADM AMPLIAÇÃO: | T3: =(SUM(PLANILHA!#REF!)-(PLANILHA!#REF!))/2 -> #REF! | V3: MED ATUAL
A4: SECRETARIA DE INFRA-ESTRUTURA - SIN | O4: MEDIÇÃO ATUAL: | P4: =P3-Q3 -> -122159.25 | S4: MEDIÇÃO ATUALREFORMA: | T4: =SUM(PLANILHA!L15:L19,PLANILHA!L21,PLANILHA!L25,PLANILHA!L29,PLANILHA!L32,PLANILHA!L34,PLANILHA!L36,PLANILHA!L51,PLANILHA!L56,PLANILHA!L59,PLANILHA!L62,PLANILHA!L64,PLANILHA!#REF!,PLANILHA!#REF!,PLANILHA!#REF!,PLANILHA!#REF!,PLANILHA!#REF!,PLANILHA!#REF!) -> #REF! | U4: 323198.85 | V4: =T4-U4 -> #REF!
A5: COORDENADORIA DE OBRAS E SERVIÇOS DE ENGENHARIA | O5: AVANÇO DA OBRA: | P5: =P4/P2 -> -0.385 | Q5: =1373261.23/2 -> 686630.62 | S5: MEDIÇÃO ATUAL AMPLIAÇÃO: | T5: =SUM(PLANILHA!#REF!)/2 -> #REF! | U5: 10346.24 | V5: =T5-U5 -> #REF!
A6: SUB-COORDENADORIA DE FISCALIZAÇÃO E CONTROLE | O6: ADM: | P6: =P5 -> -0.385 | Q6: =(141055.2-2917.43)/2 -> 69068.89 | S6: AVANÇO DA OBRA REFORMA: | T6: =V4/T2 -> #REF! | V6: =SUM(V4:V5) -> #REF!
M7: LEGENDA
N8: BM 02 | Q8: =SUM(Q5:Q6) -> 755699.51 | R8: =PLANILHA!K69 -> 335000 | S8: AVANÇO DA OBRA AMPLIAÇÃO: | T8: =V5/T3 -> #REF!
R9: =Q8-R8 -> 420699.51 | S9: ADM: | T9: =T6 -> #REF!
A10: =PLANILHA!B8 -> CONSTITUI O PRESENTE OBJETO A CONTRATAÇÃO DE EMPRESA ESPECIALIZADA PARA EXECUÇÃO DE OBRA DA COBERTURA DA QUADRA POLIESPORTIVA DO 8º BATALHÃO DE POLICIA MILITAR, LOCALIZADO NA RUA PROF. MARIO PINOTI, 218, NOVA CRUZ/RN.
A11: MEMÓRIA DE CÁLCULO - BOLETIM DE MEDIÇÃO Nº 02
A13: LEGENDA: C /P= COMPRIMENTO/PERÍMETRO; L = LARGURA; H = ALTURA; N = Nº DE REPETIÇÕES; A/V=ÁREA/VOLUME
O14: MEDIDOS
A15: ITEM | B15: DESCRIÇÃO | C15: UNID | D15: C/P | E15: L | F15: H | G15: % | H15: N | I15: Q | J15: A/V | K15: SUBTOTAL | L15: MEDIDO NO PERÍODO | M15: PREVISTO | N15: SALDO | O15: X
O16: X
A17: =PLANILHA!A13 -> 1. | B17: =VLOOKUP(A17,PLANILHA!A:N,2,FALSE) -> SERVIÇOS PRELIMINARES | O17: X
A18: =PLANILHA!A14 -> 1.1 | B18: =VLOOKUP(A18,PLANILHA!A:N,2,FALSE) -> ADMINISTRAÇÃO LOCAL DA OBRA | C18: =VLOOKUP(A18,PLANILHA!A:N,3,FALSE) -> UN | L18: =SUM(K19:K21) -> 0.35 | M18: =VLOOKUP(A18,PLANILHA!A:N,4,FALSE) -> 1 | N18: =VLOOKUP(A18,PLANILHA!A:N,7,FALSE) -> 0.42 | O18: X | P18: 17695.49
O19: X
A20: BM 02 | B20: ADMINISTRAÇÃO DE OBRA - PROPORCIONAL AO AVANÇO | G20: 0.35 | K20: =G20 -> 0.35 | O20: X | P20: 6195.01
O21: X
A22: =PLANILHA!A15 -> 1.2 | B22: =VLOOKUP(A22,PLANILHA!A:N,2,FALSE) -> REGULARIZAÇÃO DE OBRA - ART - 2025 | C22: =VLOOKUP(A22,PLANILHA!A:N,3,FALSE) -> UN | L22: =SUM(K23:K24) -> 0 | M22: =VLOOKUP(A22,PLANILHA!A:N,4,FALSE) -> 1 | N22: =VLOOKUP(A22,PLANILHA!A:N,7,FALSE) -> 0 | O22: X
O23: X
O24: X
A25: =PLANILHA!A16 -> 1.3 | B25: =VLOOKUP(A25,PLANILHA!A:N,2,FALSE) -> FORNECIMENTO E INSTALAÇÃO DE PLACA DE OBRA COM CHAPA GALVANIZADA E ESTRUTURA DE MADEIRA. AF_03/2022_PS | C25: =VLOOKUP(A25,PLANILHA!A:N,3,FALSE) -> m² | L25: =SUM(K26:K27) -> 0 | M25: =VLOOKUP(A25,PLANILHA!A:N,4,FALSE) -> 6 | N25: =VLOOKUP(A25,PLANILHA!A:N,7,FALSE) -> 0 | O25: X
O26: X
O27: X
A28: =PLANILHA!A17 -> 1.4 | B28: =VLOOKUP(A28,PLANILHA!A:N,2,FALSE) -> MOBILIZAÇÃO DE EQUIPAMENTOS EM CAMINHÃO EQUIPADO COM GUINDASTE | C28: =VLOOKUP(A28,PLANILHA!A:N,3,FALSE) -> KM | L28: =SUM(K29:K30) -> 0 | M28: =VLOOKUP(A28,PLANILHA!A:N,4,FALSE) -> 50 | N28: =VLOOKUP(A28,PLANILHA!A:N,7,FALSE) -> 0 | O28: X
O29: X
O30: X
A31: =PLANILHA!A18 -> 1.5 | B31: =VLOOKUP(A31,PLANILHA!A:N,2,FALSE) -> DEMOLIÇÃO DE PISO DE CIMENTADO SOBRE LASTRO DE CONCRETO SIMPLES/CALCETAMENTO. R_11/2020 | C31: =VLOOKUP(A31,PLANILHA!A:N,3,FALSE) -> m² | L31: =SUM(K32:K33) -> 0 | M31: =VLOOKUP(A31,PLANILHA!A:N,4,FALSE) -> 23.66 | N31: =VLOOKUP(A31,PLANILHA!A:N,7,FALSE) -> 0.01 | O31: X
O32: X
O33: X
A34: =PLANILHA!A19 -> 1.6 | B34: =VLOOKUP(A34,PLANILHA!A:N,2,FALSE) -> DEMOLIÇÃO DE ALVENARIA DE BLOCO FURADO, DE FORMA MANUAL, SEM REAPROVEITAMENTO. AF_09/2023 | C34: =VLOOKUP(A34,PLANILHA!A:N,3,FALSE) -> m³ | L34: =SUM(K35:K36) -> 0 | M34: =VLOOKUP(A34,PLANILHA!A:N,4,FALSE) -> 3.46 | N34: =VLOOKUP(A34,PLANILHA!A:N,7,FALSE) -> 0 | O34: X
O35: X
O36: X
A37: =PLANILHA!A20 -> 1.7 | B37: =VLOOKUP(A37,PLANILHA!A:N,2,FALSE) -> REMOÇÃO DE POSTE DE CONCRETO ARMADO SEÇÃO CIRCULAR OU DUPLO T. INC_05/2021 | C37: =VLOOKUP(A37,PLANILHA!A:N,3,FALSE) -> un | L37: =SUM(K38:K39) -> 0 | M37: =VLOOKUP(A37,PLANILHA!A:N,4,FALSE) -> 3 | N37: =VLOOKUP(A37,PLANILHA!A:N,7,FALSE) -> 0 | O37: X
O38: X
O39: X
A40: =PLANILHA!A21 -> 2 | B40: =PLANILHA!B21 -> MOVIMENTO DE TERRA | O40: X
A41: =PLANILHA!A22 -> 2.1 | B41: =VLOOKUP(A41,PLANILHA!A:N,2,FALSE) -> ESCAVAÇÃO MANUAL PARA BLOCO DE COROAMENTO OU SAPATA (INCLUINDO ESCAVAÇÃO PARA COLOCAÇÃO DE FÔRMAS). AF_01/2024 | C41: =VLOOKUP(A41,PLANILHA!A:N,3,FALSE) -> m³ | L41: =SUM(K42:K43) -> 0 | M41: =VLOOKUP(A41,PLANILHA!A:N,4,FALSE) -> 23.96 | N41: =VLOOKUP(A41,PLANILHA!A:N,7,FALSE) -> 0.2 | O41: X | P41: READEQUAÇÃO
O42: X
...
